# 错误处理

错误处理是响应程序中的错误条件，并从错误中恢复的过程。Swift为在运行时抛出，捕获，传递和操作可恢复错误提供了最高级别的支持。

有一些操作并不能保证总是能完成执行或产生有用的输出。可选值用来呈现某一个值，但是当一个操作失败时，能弄懂什么导致了失败比较有用，那样你的代码就可以作出相应的响应。

例如，考虑一下从磁盘文件中读取并处理数据的任务。这个任务有多种失败的可能，包括指定路径的文件不存在，文件没有读取权限，或文件编码格式不兼容。区分这些错误情形能让程序解决一些错误，并可以告诉用户一些错误无法解决。

> 注意：
> Swift中的错误处理与Cocoa和Objective-C中的`NSError`类的错误处理模式相互协调。关于此类的更多信息，参见[Handling Cocoa Errors in Swift](https://developer.apple.com/documentation/swift/cocoa_design_patterns/handling_cocoa_errors_in_swift)。

## 表达并抛出错误

在Swift中，用实现了`Error`协议类型的值表达错误。这个空协议表明一个类型可以用来处理错误。

Swift中的枚举更适合为一组相关的错误条件建模，用关联值则可以表达与要处理错误本质相关的额外信息。例如，可以这样表达在游戏中操作自动售货机的错误条件：
```swift
enum VendingMachineError: Error {
    case invalidSelection
    case insufficientFunds(coinsNeeded: Int)
    case outOfStock
}
```

抛出一个错误表明发生异常，正常的流程无法继续。用`throw`语句抛出错误。例如，下面的代码抛出一个错误表明自动售货机需要额外五枚硬币：
```swift
throw VendingMachineError.insufficientFunds(coinsNeeded: 5)
```

## 处理错误

当一个错误被抛出，错误周围的代码片段必须为处理错误作出反应---例如，修复问题，尝试另一个操作或通知用户失败。

在Swift中有四种处理错误的方法。可以把错误从函数传递到调用该函数的代码，用`do-catch`语句，将错误当作可选值处理或断言该错误不会发生。下面分别介绍。

函数抛出错误时，会改变程序流程，所以能快速定位抛出错误的代码很重要。为了定位这些错误，在调用可能抛出错误的函数，方法或初始化方法前写上`try`关键字---或`try?`或`try!`变体。这些关键字在下面的章节中有描述。

> 注意：
> Swift中的错误处理与其他语言中的异常处理相似，都用了`try`，`catch`和`throw`等关键字。与其他许多语言–––包括Objective-C–––的异常处理不同的是，Swift中的错误处理不涉及展开调用堆栈，这是一个计算成本高昂的过程。因此，`throw`语句的表现特性相当于一个`return`语句。（译者：🐂👃呀）

### 用报错函数传递错误

为了表明一个函数，方法后初始化方法可以抛出错误，你可以在函数声明的参数后面写上`throws`关键字。用`throws`关键字标记的函数称为*报错函数*。如果函数指定了返回类型，则在返回箭头(`->`)前面写上`throws`关键字。
```swift
func canThrowErrors() throws -> String

func cannotThrowErrors() -> String
```

一个报错函数将其内部抛出的错误，传递给调用该函数的代码块。

> 注意：
> 只有报错函数能传递错误。任何在非报错函数内部抛出的错误必须在其内部处理。

下面的例子中，类`VendingMachine`有一个方法`vend(itemNamed:)`，如果请求的项不可用，缺货或需要超出当前金额的费用时，就抛出相应`VendingMachineError`错误：
```swift
struct Item {
    var price: Int
    var count: Int
}

class VendingMachine {
    var inventory = [
      "Candy Bar": Item(price: 12, count: 7),
      "Chips": Item(price: 10, count: 4),
      "Pretzels": Item(price: 7, count: 11)
    ]
    var coinsDeposited = 0

    func vend(itemNamed name: String) throws {
        guard let item = inventory[name] else {
            throw VendingMachineError.invalidSelection
        }

        guard item.count > 0 else {
            throw VendingMachineError.outOfStock
        }

        guard item.price <= coinsDeposited else {
            throw VendingMachineError.insufficientFunds(coinsNeeded: item.price - coinsDeposited)
        }

        coinsDeposited -= item.price

        var newItem = item
        newItem.count -= 1
        inventory[name] = newItem

        print("Dispensing \(name)")
    }
}
```

`vend(itemNamed:)`方法的声明中，用`guard`语句提前退出方法，并在任何购买糖果的要求不被满足时抛出相应的错误。因为`throw`语句立即转移了程序流程，只有当所有的要求都被满足时才会售出一个货物。

因为`vend(itemNamed:)`方法会传递任何抛出的错误，任何调用此方法的代码必须处理错误---用`do-catch`语句，或用`try?`或`try!`---传递它们。例如，下面例子中的`buyFavoriteSnack(person:vendingMachine:)`也是一个报错函数，`vend(itemNamed:)`抛出的任何错误都会传递到`buyFavoriteSnack(person:vendingMachine:)`函数被调用的地方。
```swift
let favoriteSnacks = [
    "Alice": "Chips",
    "Bob": "Licorice",
    "Eve": "Pretzels",
]
func buyFavoriteSnack(person: String, vendingMachine: VendingMachine) throws {
    let snackName = favoriteSnacks[person] ?? "Candy Bar"
    try vendingMachine.vend(itemNamed: snackName)
}
```

这个例子中，`buyFavoriteSnack(person:vendingMachine:)`函数查找给定人物最喜欢的糖果，然后试图通过调用`vend(itemNamed:)`方法购买。因为`vend(itemNamed:)`方法可以抛出错误，所以在方法名之前写上`try`关键字来调用。

报错初始化方法与报错函数一样可以传递错误。例如，下面的`PurchasedSnack`结构体的初始化方法，调用一个报错函数作为初始化处理的一部分，它会通过将遇到的错误传递给调用者的方式处理错误。
```swift
struct PurchasedSnack {
    let name: String
    init(name: String, vendingMachine: VendingMachine) throws {
        try vendingMachine.vend(itemNamed: name)
        self.name = name
    }
}
```

### 用`Do-Catch`处理错误

用`do-catch`语句执行一个语句块来处理错误。如果一个错误在`do`子句中被抛出，会被用于匹配`catch`子句，以决定哪一个`catch`子句可以处理错误：

下面是`do-catch`语句的一般格式：
```swift
do {
    try expression
    statements
} catch pattern 1 {
    statements
} catch pattern 2 where condition {
    statements
} catch {
    statements
}
```

在`catch`后面写上模式来表明该子句可以处理什么错误。如果`catch`子句没有模式，则该子句匹配任何错误，且将错误绑定给一个局部常量`error`。关于模式匹配的更多信息，参见[模式](../Language_Reference/Patterns.md)。

例如，下面的代码匹配`VendingMachineError`枚举的三个分支：
```swift
var vendingMachine = VendingMachine()
vendingMachine.coinsDeposited = 8
do {
    try buyFavoriteSnack(person: "Alice", vendingMachine: vendingMachine)
    print("Success! Yum.")
} catch VendingMachineError.invalidSelection {
    print("Invalid Selection.")
} catch VendingMachineError.outOfStock {
    print("Out of Stock.")
} catch VendingMachineError.insufficientFunds(let coinsNeeded) {
    print("Insufficient funds. Please insert an additional \(coinsNeeded) coins.")
} catch {
    print("Unexpected error: \(error).")
}
// Prints "Insufficient funds. Please insert an additional 2 coins."
```

在上面的例子中，因为能抛出错误，函数`buyFavoriteSnack(person:vendingMachine:)`被`try`语句调用。如果抛出了错误，代码执行会立即跳转到`catch`子句，该子句决定是否允许继续传递错误。如果匹配的模式，错误会被最后的`catch`子句捕获，并被打包在局部常量`error`中。如果没有错误抛出，`do`语句中剩下的语句会被执行。

`catch`子句不需要处理每一个可能从`do`语句中抛出的错误。如果没有`catch`子句处理错误，错误将被传递到周围的区域。但是，传递的错误必须被周围的代码处理。在一个非报错函数中，一个封闭的`do-catch`必须处理错误。在报错函数中，`do-catch`或调用者必须处理错误。如果不处理错误任由其被传递到了顶级作用域，将会得到一个运行时错误。

例如，上面的例子可以这样写，任何非`VendingMachineError`的错误会被函数捕获：
```swift
func nourish(with item: String) throws {
    do {
        try vendingMachine.vend(itemNamed: item)
    } catch is VendingMachineError {
        print("Invalid selection, out of stock, or not enough money.")
    }
}

do {
    try nourish(with: "Beet-Flavored Chips")
} catch {
    print("Unexpected non-vending-machine-related error: \(error)")
}
// Prints "Invalid selection, out of stock, or not enough money."
```

在`nourish(with:)`函数中，如果`vend(itemNamed:)`抛出枚举`VendingMachineError`中的一个错误，`nourish(with:)`会通过打印信息来处理错误。否则，`nourish(with:)`将错误传递到被调用的地方。然后，错误会被一般的`catch`子句捕获。

### 将错误转换为可选值

用`try?`将错误转换为可选值来处理错误。如果计算`try?`表达式时抛出了错误，则该表达式的值为`nil`。例如，下面代码中的`x`和`y`有相同的值和行为：
```swift
func someThrowingFunction() throws -> Int {
    // ...
}

let x = try? someThrowingFunction()

let y: Int?
do {
    y = try someThrowingFunction()
} catch {
    y = nil
}
```

如果函数`someThrowingFunction()`抛出错误，`x`和`y`的值就是`nil`。否则，`x`和`y`的值就是函数的返回值。注意`x`和`y`是`someThrowingFunction()`返回类型的可选类型。这里函数返回一个整型，所以`x`和`y`是可选整型。

当想用相同方式处理错误时，用`try?`可以使你编写简洁的错误处理代码。例如，下面的代码用几个步骤获取数据，或者，如果所有的步骤都失败，就返回`nil`。
```swift
func fetchData() -> Data? {
    if let data = try? fetchDataFromDisk() { return data }
    if let data = try? fetchDataFromServer() { return data }
    return nil
}
```

### 禁用错误传递

事实上，有时候你知道一个报错方法或报错函数不会在运行时抛出错误。这种情况下，可以在表达式前写上`try!`来禁用错误传递，并将调用括在不会抛出错误的运行时断言中。如果真的有错误抛出，你将获得一个运行时错误。

举个例子，下面的代码使用了一个函数`loadImage(atPath:)`，该函数会加载指定路径的图片资源，如果不能加载图片就会抛出错误。这种情况下，因为图片是随附在应用程序中，在运行时不会抛出错误，所以禁用错误传递比较合适。
```swift
let photo = try! loadImage(atPath: "./Resources/JohnAppleseed.jpg")
```

## 指定清理操作

用`defer`语句在代码执行即将离开当前代码块时执行一组语句。不管代码执行如何离开当前代码块---无论是因为抛出错误而离开还是因为诸如`return`或`break`这样的语句而离开，这个语句能让你执行必要的清理操作。举个例子，你可以用`defer`语句确保文件描述符被关闭，手动分配的内存被释放。

一个`defer`语句延迟到退出当前作用域时才执行。这个语句由`defer`关键字和其后需要被执行的语句组成。延迟执行语句不能包含跳出语句控制流的代码，例如`break`或`return`语句，或抛出错误。延迟操作以书写代码顺序的逆序被执行。也就是，`defer`语句的第一行代码最后被执行，第二行代码倒数第二被执行，等等。代码中最后的`defer`语句首先被执行。
```swift
func processFile(filename: String) throws {
    if exists(filename) {
        let file = open(filename)
        defer {
            close(file)
        }
        while let line = try file.readline() {
            // Work with the file.
        }
        // close(file) is called here, at the end of the scope.
    }
}
```

上面的例子用`defer`语句确保`open(_:)`函数会相应地调用`close(_:)`。

> 注意：
> 即使不涉及到错误处理，你也可以用`defer`语句。

[< 可选链](16.Optional_Chaining.md) || [类型转换 >](20.Type_Casting.md)
